{
 "cells": [
  {
   "cell_type": "markdown",
   "id": "2c25fcff-781b-4560-857e-d3dcda7d410c",
   "metadata": {},
   "source": [
    "#### Errors and Exceptions"
   ]
  },
  {
   "cell_type": "markdown",
   "id": "f3979883-788d-4007-ab4f-5edf473e19d2",
   "metadata": {},
   "source": [
    "Until now error messages haven’t been more than mentioned, but if you have tried out the examples you have probably seen some. There are (at least) two distinguishable kinds of errors: syntax errors and exceptions."
   ]
  },
  {
   "cell_type": "markdown",
   "id": "d42bd369-75e7-47d9-a0d9-fd10c63edf6e",
   "metadata": {},
   "source": [
    "#### Syntax Errors"
   ]
  },
  {
   "cell_type": "markdown",
   "id": "ab4c05a2-1b20-4c01-85c4-eb34e24b509a",
   "metadata": {},
   "source": [
    "Syntax errors, also known as parsing errors, are perhaps the most common kind of complaint you get while you are still learning Python:"
   ]
  },
  {
   "cell_type": "code",
   "execution_count": 1,
   "id": "aae3870e-4b4c-4da8-84f2-d87f18aca64a",
   "metadata": {},
   "outputs": [
    {
     "ename": "SyntaxError",
     "evalue": "invalid syntax (2884618176.py, line 1)",
     "output_type": "error",
     "traceback": [
      "\u001b[1;36m  Cell \u001b[1;32mIn[1], line 1\u001b[1;36m\u001b[0m\n\u001b[1;33m    while True print('Hello world')\u001b[0m\n\u001b[1;37m               ^\u001b[0m\n\u001b[1;31mSyntaxError\u001b[0m\u001b[1;31m:\u001b[0m invalid syntax\n"
     ]
    }
   ],
   "source": [
    "while True print('Hello world')"
   ]
  },
  {
   "cell_type": "markdown",
   "id": "4550fe16-d453-495f-96c2-c7066f78b7b7",
   "metadata": {},
   "source": [
    "The parser repeats the offending line and displays little arrows pointing at the token in the line where the error was detected. The error may be caused by the absence of a token before the indicated token. In the example, the error is detected at the function print(), since a colon (':') is missing before it. File name and line number are printed so you know where to look in case the input came from a script."
   ]
  },
  {
   "cell_type": "markdown",
   "id": "c1752292-7a72-4712-b6a0-38ae7fa0ddaa",
   "metadata": {},
   "source": [
    "#### Exceptions\n",
    "\n",
    "Even if a statement or expression is syntactically correct, it may cause an error when an attempt is made to execute it. Errors detected during execution are called exceptions and are not unconditionally fatal: you will soon learn how to handle them in Python programs. Most exceptions are not handled by programs, however, and result in error messages as shown here:"
   ]
  },
  {
   "cell_type": "code",
   "execution_count": 2,
   "id": "00a17872-4316-4d7f-b864-e19e3037fc9e",
   "metadata": {},
   "outputs": [
    {
     "ename": "ZeroDivisionError",
     "evalue": "division by zero",
     "output_type": "error",
     "traceback": [
      "\u001b[1;31m---------------------------------------------------------------------------\u001b[0m",
      "\u001b[1;31mZeroDivisionError\u001b[0m                         Traceback (most recent call last)",
      "Cell \u001b[1;32mIn[2], line 1\u001b[0m\n\u001b[1;32m----> 1\u001b[0m \u001b[38;5;28mprint\u001b[39m(\u001b[38;5;241m10\u001b[39m \u001b[38;5;241m*\u001b[39m (\u001b[38;5;241;43m1\u001b[39;49m\u001b[38;5;241;43m/\u001b[39;49m\u001b[38;5;241;43m0\u001b[39;49m))\n",
      "\u001b[1;31mZeroDivisionError\u001b[0m: division by zero"
     ]
    }
   ],
   "source": [
    "print(10 * (1/0))"
   ]
  },
  {
   "cell_type": "code",
   "execution_count": 3,
   "id": "52b5685b-b81a-47db-85e1-df78f48c2034",
   "metadata": {},
   "outputs": [
    {
     "ename": "NameError",
     "evalue": "name 'spam' is not defined",
     "output_type": "error",
     "traceback": [
      "\u001b[1;31m---------------------------------------------------------------------------\u001b[0m",
      "\u001b[1;31mNameError\u001b[0m                                 Traceback (most recent call last)",
      "Cell \u001b[1;32mIn[3], line 1\u001b[0m\n\u001b[1;32m----> 1\u001b[0m \u001b[38;5;28mprint\u001b[39m(\u001b[38;5;241m4\u001b[39m \u001b[38;5;241m+\u001b[39m \u001b[43mspam\u001b[49m\u001b[38;5;241m*\u001b[39m\u001b[38;5;241m3\u001b[39m)\n",
      "\u001b[1;31mNameError\u001b[0m: name 'spam' is not defined"
     ]
    }
   ],
   "source": [
    "print(4 + spam*3)"
   ]
  },
  {
   "cell_type": "code",
   "execution_count": 4,
   "id": "be38a984-9cd9-485a-a38b-e4fa05efb107",
   "metadata": {},
   "outputs": [
    {
     "ename": "TypeError",
     "evalue": "can only concatenate str (not \"int\") to str",
     "output_type": "error",
     "traceback": [
      "\u001b[1;31m---------------------------------------------------------------------------\u001b[0m",
      "\u001b[1;31mTypeError\u001b[0m                                 Traceback (most recent call last)",
      "Cell \u001b[1;32mIn[4], line 1\u001b[0m\n\u001b[1;32m----> 1\u001b[0m \u001b[38;5;28mprint\u001b[39m(\u001b[38;5;124;43m'\u001b[39;49m\u001b[38;5;124;43m2\u001b[39;49m\u001b[38;5;124;43m'\u001b[39;49m\u001b[43m \u001b[49m\u001b[38;5;241;43m+\u001b[39;49m\u001b[43m \u001b[49m\u001b[38;5;241;43m2\u001b[39;49m)\n",
      "\u001b[1;31mTypeError\u001b[0m: can only concatenate str (not \"int\") to str"
     ]
    }
   ],
   "source": [
    "print('2' + 2)"
   ]
  },
  {
   "cell_type": "markdown",
   "id": "8289bc43-bd9d-4bdb-b02b-be62d384b20e",
   "metadata": {},
   "source": [
    "The last line of the error message indicates what happened. Exceptions come in different types, and the type is printed as part of the message: the types in the example are [ZeroDivisionError](https://docs.python.org/3/library/exceptions.html#ZeroDivisionError), [NameError](https://docs.python.org/3/library/exceptions.html#NameError) and [TypeError](https://docs.python.org/3/library/exceptions.html#TypeError). The string printed as the exception type is the name of the built-in exception that occurred. This is true for all built-in exceptions, but need not be true for user-defined exceptions (although it is a useful convention). Standard exception names are built-in identifiers (not reserved keywords).\n",
    "\n",
    "The rest of the line provides detail based on the type of exception and what caused it.\n",
    "\n",
    "The preceding part of the error message shows the context where the exception occurred, in the form of a stack traceback. In general it contains a stack traceback listing source lines; however, it will not display lines read from standard input.\n",
    "\n",
    "[Built-in Exceptions](https://docs.python.org/3/library/exceptions.html#bltin-exceptions) lists the built-in exceptions and their meanings."
   ]
  },
  {
   "cell_type": "markdown",
   "id": "2e85614a-3070-42aa-9cf1-ee3e316e48b0",
   "metadata": {},
   "source": [
    "#### Handling Exceptions"
   ]
  },
  {
   "cell_type": "code",
   "execution_count": 5,
   "id": "0a849b0e-788a-4ec1-99b2-190234dad319",
   "metadata": {},
   "outputs": [
    {
     "name": "stdin",
     "output_type": "stream",
     "text": [
      "Enter a number:  62\n"
     ]
    }
   ],
   "source": [
    "while True:\n",
    "    try:\n",
    "        x = int(input(\"Enter a number: \"))\n",
    "        break\n",
    "    except ValueError:\n",
    "        print(\"This is not a valid number. Try again...\")"
   ]
  },
  {
   "cell_type": "markdown",
   "id": "fe9ba3c4-02fb-4e00-8e78-09a3b76d007d",
   "metadata": {},
   "source": [
    "A class in an [except](https://docs.python.org/3/reference/compound_stmts.html#except) clause matches exceptions which are instances of the class itself or one of its derived classes (but not the other way around — an except clause listing a derived class does not match instances of its base classes). For example, the following code will print B, C, D in that order:"
   ]
  },
  {
   "cell_type": "code",
   "execution_count": 6,
   "id": "f15e0556-69f7-42f5-a02e-f1bbc310baef",
   "metadata": {},
   "outputs": [
    {
     "name": "stdout",
     "output_type": "stream",
     "text": [
      "B\n",
      "C\n",
      "D\n"
     ]
    }
   ],
   "source": [
    "class B(Exception):\n",
    "    pass\n",
    "class C(B):\n",
    "    pass\n",
    "class D(C):\n",
    "    pass\n",
    "for cls in [B,C, D]:\n",
    "    try:\n",
    "        raise cls()\n",
    "    except D:\n",
    "        print(\"D\")\n",
    "    except C:\n",
    "        print(\"C\")\n",
    "    except B:\n",
    "        print(\"B\")\n",
    "\n",
    "    # except B:\n",
    "    #     print(\"B\")\n",
    "    # except D:\n",
    "    #     print(\"D\")\n",
    "    # except C:\n",
    "    #     print(\"C\")\n",
    "    "
   ]
  },
  {
   "cell_type": "markdown",
   "id": "a8dab05e-3b1b-4645-a595-602a4ca0b9c4",
   "metadata": {},
   "source": [
    "Note that if the except clauses were reversed (with except B first), it would have printed B, B, B — the first matching except clause is triggered.\n",
    "\n",
    "When an exception occurs, it may have associated values, also known as the exception’s arguments. The presence and types of the arguments depend on the exception type.\n",
    "\n",
    "The except clause may specify a variable after the exception name. The variable is bound to the exception instance which typically has an `args` attribute that stores the arguments. For convenience, builtin exception types define `__str__()` to print all the arguments without explicitly accessing .args."
   ]
  },
  {
   "cell_type": "code",
   "execution_count": 7,
   "id": "5db3f19d-3f6a-4eca-9195-7c0c5956eea2",
   "metadata": {},
   "outputs": [
    {
     "name": "stdout",
     "output_type": "stream",
     "text": [
      "<class 'Exception'>\n",
      "('spam', 'eggs')\n",
      "('spam', 'eggs')\n",
      "x = spam\n",
      "y = eggs\n"
     ]
    }
   ],
   "source": [
    "try:\n",
    "    raise Exception('spam', 'eggs')\n",
    "except Exception as inst:\n",
    "    print(type(inst))    # the exception type\n",
    "    print(inst.args)     # arguments stored in .args\n",
    "    print(inst)          # __str__ allows args to be printed directly,\n",
    "                         # but may be overridden in exception subclasses\n",
    "    x, y = inst.args     # unpack args\n",
    "    print('x =', x)\n",
    "    print('y =', y)"
   ]
  },
  {
   "cell_type": "markdown",
   "id": "7f9bda38-4c35-4cdd-92a2-6ba6c59571d6",
   "metadata": {},
   "source": [
    "The exception’s `__str__()` output is printed as the last part (‘detail’) of the message for unhandled exceptions.\n",
    "\n",
    "`BaseException` is the common base class of all exceptions. One of its subclasses, `Exception`, is the base class of all the non-fatal exceptions. Exceptions which are not subclasses of `Exception` are not typically handled, because they are used to indicate that the program should terminate. They include `SystemExit` which is raised by `sys.exit()` and `KeyboardInterrupt` which is raised when a user wishes to interrupt the program.\n",
    "\n",
    "`Exception` can be used as a wildcard that catches (almost) everything. However, it is good practice to be as specific as possible with the types of exceptions that we intend to handle, and to allow any unexpected exceptions to propagate on.\n",
    "\n",
    "The most common pattern for handling `Exception` is to print or log the exception and then re-raise it (allowing a caller to handle the exception as well):"
   ]
  },
  {
   "cell_type": "code",
   "execution_count": 8,
   "id": "1fcbd149-ca5e-47da-8b9c-e5113ba67778",
   "metadata": {},
   "outputs": [
    {
     "name": "stdout",
     "output_type": "stream",
     "text": [
      "Could not convert data to an integer\n"
     ]
    }
   ],
   "source": [
    "import sys\n",
    "try:\n",
    "    f = open('workfile')\n",
    "    s = f.readline()\n",
    "    i = int(s.strip())\n",
    "except OSError as err:\n",
    "    print(\"OS errors:\", err)\n",
    "except ValueError:\n",
    "    print(\"Could not convert data to an integer\")\n",
    "except Exception as err:\n",
    "    print(f\"Unexpected {err}, {type(err)}\")\n",
    "    raise"
   ]
  },
  {
   "cell_type": "markdown",
   "id": "5cfe503a-6617-43ac-99bb-129a1533d5b7",
   "metadata": {},
   "source": [
    "The `try … except` statement has an optional else clause, which, when present, must follow all except clauses. It is useful for code that must be executed if the try clause does not raise an exception. For example:"
   ]
  },
  {
   "cell_type": "code",
   "execution_count": 9,
   "id": "498f45e7-8ad4-4576-8b2a-f91b9aa9a871",
   "metadata": {},
   "outputs": [
    {
     "name": "stdout",
     "output_type": "stream",
     "text": [
      "cannot open -f\n",
      "C:\\Users\\PC\\AppData\\Roaming\\jupyter\\runtime\\kernel-74065eb8-76b2-4259-8683-eb0365a3ff15.json has 13 lines\n"
     ]
    }
   ],
   "source": [
    "for arg in sys.argv[1:]:\n",
    "    try:\n",
    "        f = open(arg, 'r')\n",
    "    except OSError:\n",
    "        print('cannot open', arg)\n",
    "    else:\n",
    "        print(arg, 'has', len(f.readlines()), 'lines')\n",
    "        f.close()"
   ]
  },
  {
   "cell_type": "markdown",
   "id": "de350799-3d5b-48ca-b7fe-7c3f3301a5fa",
   "metadata": {},
   "source": [
    "The use of the `else` clause is better than adding additional code to the `try` clause because it avoids accidentally catching an exception that wasn’t raised by the code being protected by the `try … except` statement.\n",
    "\n",
    "Exception handlers do not handle only exceptions that occur immediately in the try clause, but also those that occur inside functions that are called (even indirectly) in the try clause. For example:"
   ]
  },
  {
   "cell_type": "code",
   "execution_count": 10,
   "id": "a7119f3a-1246-4a23-9e3d-ed3655db7df8",
   "metadata": {},
   "outputs": [
    {
     "name": "stdout",
     "output_type": "stream",
     "text": [
      "Handling run-time error: division by zero\n"
     ]
    }
   ],
   "source": [
    "def fails():\n",
    "    x = 1/0\n",
    "\n",
    "try:\n",
    "    fails()\n",
    "except ZeroDivisionError as err:\n",
    "    print(\"Handling run-time error:\", err)"
   ]
  },
  {
   "cell_type": "markdown",
   "id": "e6ee2b6e-ced8-4a3d-ad80-d76275c24cd1",
   "metadata": {},
   "source": [
    "#### Raising Exceptions"
   ]
  },
  {
   "cell_type": "markdown",
   "id": "0c9fac50-541b-4750-bffb-79b4185d36bd",
   "metadata": {},
   "source": [
    "The `raise` statement allows the programmer to force a specified exception to occur. For example:"
   ]
  },
  {
   "cell_type": "code",
   "execution_count": 11,
   "id": "40326b93-9bff-4681-a64f-b86e805a1ad5",
   "metadata": {},
   "outputs": [
    {
     "ename": "NameError",
     "evalue": "Mistake, invalid symbols entered",
     "output_type": "error",
     "traceback": [
      "\u001b[1;31m---------------------------------------------------------------------------\u001b[0m",
      "\u001b[1;31mNameError\u001b[0m                                 Traceback (most recent call last)",
      "Cell \u001b[1;32mIn[11], line 1\u001b[0m\n\u001b[1;32m----> 1\u001b[0m \u001b[38;5;28;01mraise\u001b[39;00m \u001b[38;5;167;01mNameError\u001b[39;00m(\u001b[38;5;124m\"\u001b[39m\u001b[38;5;124mMistake, invalid symbols entered\u001b[39m\u001b[38;5;124m\"\u001b[39m)\n",
      "\u001b[1;31mNameError\u001b[0m: Mistake, invalid symbols entered"
     ]
    }
   ],
   "source": [
    "raise NameError(\"Mistake, invalid symbols entered\")"
   ]
  },
  {
   "cell_type": "markdown",
   "id": "ffcec840-230c-4529-87cf-736ed842ff5b",
   "metadata": {},
   "source": [
    "The sole argument to `raise` indicates the exception to be raised. This must be either an exception instance or an exception class (a class that derives from `BaseException`, such as `Exception` or one of its subclasses). If an exception class is passed, it will be implicitly instantiated by calling its constructor with no arguments:\n",
    "\n",
    "```\n",
    "raise ValueError\n",
    "```"
   ]
  },
  {
   "cell_type": "markdown",
   "id": "7d508571-06df-40f3-b184-77cbde61f285",
   "metadata": {},
   "source": [
    "If you need to determine whether an exception was raised but don’t intend to handle it, a simpler form of the `raise` statement allows you to re-raise the exception:"
   ]
  },
  {
   "cell_type": "code",
   "execution_count": 12,
   "id": "ddd2b24e-1374-407c-b734-7aba846f2a9a",
   "metadata": {},
   "outputs": [
    {
     "name": "stdout",
     "output_type": "stream",
     "text": [
      "An exception flew by\n"
     ]
    },
    {
     "ename": "NameError",
     "evalue": "Mistake, invalid symbols entered",
     "output_type": "error",
     "traceback": [
      "\u001b[1;31m---------------------------------------------------------------------------\u001b[0m",
      "\u001b[1;31mNameError\u001b[0m                                 Traceback (most recent call last)",
      "Cell \u001b[1;32mIn[12], line 2\u001b[0m\n\u001b[0;32m      1\u001b[0m \u001b[38;5;28;01mtry\u001b[39;00m:\n\u001b[1;32m----> 2\u001b[0m     \u001b[38;5;28;01mraise\u001b[39;00m \u001b[38;5;167;01mNameError\u001b[39;00m(\u001b[38;5;124m\"\u001b[39m\u001b[38;5;124mMistake, invalid symbols entered\u001b[39m\u001b[38;5;124m\"\u001b[39m)\n\u001b[0;32m      3\u001b[0m \u001b[38;5;28;01mexcept\u001b[39;00m \u001b[38;5;167;01mNameError\u001b[39;00m:\n\u001b[0;32m      4\u001b[0m     \u001b[38;5;28mprint\u001b[39m(\u001b[38;5;124m\"\u001b[39m\u001b[38;5;124mAn exception flew by\u001b[39m\u001b[38;5;124m\"\u001b[39m)\n",
      "\u001b[1;31mNameError\u001b[0m: Mistake, invalid symbols entered"
     ]
    }
   ],
   "source": [
    "try:\n",
    "    raise NameError(\"Mistake, invalid symbols entered\")\n",
    "except NameError:\n",
    "    print(\"An exception flew by\")\n",
    "    raise"
   ]
  },
  {
   "cell_type": "markdown",
   "id": "8570f6ec-c9f7-4af7-87ea-09bc726c7b0f",
   "metadata": {},
   "source": [
    "#### Exception Chaining\n",
    "If an unhandled exception occurs inside an `except` section, it will have the exception being handled attached to it and included in the error message:"
   ]
  },
  {
   "cell_type": "code",
   "execution_count": 13,
   "id": "64c6a8a8-1ec8-4026-945c-fb6f46bf3ee9",
   "metadata": {},
   "outputs": [
    {
     "ename": "RuntimeError",
     "evalue": "unable to handle error",
     "output_type": "error",
     "traceback": [
      "\u001b[1;31m---------------------------------------------------------------------------\u001b[0m",
      "\u001b[1;31mFileNotFoundError\u001b[0m                         Traceback (most recent call last)",
      "Cell \u001b[1;32mIn[13], line 2\u001b[0m\n\u001b[0;32m      1\u001b[0m \u001b[38;5;28;01mtry\u001b[39;00m:\n\u001b[1;32m----> 2\u001b[0m     \u001b[38;5;28;43mopen\u001b[39;49m\u001b[43m(\u001b[49m\u001b[38;5;124;43m\"\u001b[39;49m\u001b[38;5;124;43mnortind_small.sqlite\u001b[39;49m\u001b[38;5;124;43m\"\u001b[39;49m\u001b[43m)\u001b[49m\n\u001b[0;32m      3\u001b[0m \u001b[38;5;28;01mexcept\u001b[39;00m \u001b[38;5;167;01mOSError\u001b[39;00m:\n",
      "File \u001b[1;32mC:\\Program Files\\Python312\\Lib\\site-packages\\IPython\\core\\interactiveshell.py:324\u001b[0m, in \u001b[0;36m_modified_open\u001b[1;34m(file, *args, **kwargs)\u001b[0m\n\u001b[0;32m    318\u001b[0m     \u001b[38;5;28;01mraise\u001b[39;00m \u001b[38;5;167;01mValueError\u001b[39;00m(\n\u001b[0;32m    319\u001b[0m         \u001b[38;5;124mf\u001b[39m\u001b[38;5;124m\"\u001b[39m\u001b[38;5;124mIPython won\u001b[39m\u001b[38;5;124m'\u001b[39m\u001b[38;5;124mt let you open fd=\u001b[39m\u001b[38;5;132;01m{\u001b[39;00mfile\u001b[38;5;132;01m}\u001b[39;00m\u001b[38;5;124m by default \u001b[39m\u001b[38;5;124m\"\u001b[39m\n\u001b[0;32m    320\u001b[0m         \u001b[38;5;124m\"\u001b[39m\u001b[38;5;124mas it is likely to crash IPython. If you know what you are doing, \u001b[39m\u001b[38;5;124m\"\u001b[39m\n\u001b[0;32m    321\u001b[0m         \u001b[38;5;124m\"\u001b[39m\u001b[38;5;124myou can use builtins\u001b[39m\u001b[38;5;124m'\u001b[39m\u001b[38;5;124m open.\u001b[39m\u001b[38;5;124m\"\u001b[39m\n\u001b[0;32m    322\u001b[0m     )\n\u001b[1;32m--> 324\u001b[0m \u001b[38;5;28;01mreturn\u001b[39;00m \u001b[43mio_open\u001b[49m\u001b[43m(\u001b[49m\u001b[43mfile\u001b[49m\u001b[43m,\u001b[49m\u001b[43m \u001b[49m\u001b[38;5;241;43m*\u001b[39;49m\u001b[43margs\u001b[49m\u001b[43m,\u001b[49m\u001b[43m \u001b[49m\u001b[38;5;241;43m*\u001b[39;49m\u001b[38;5;241;43m*\u001b[39;49m\u001b[43mkwargs\u001b[49m\u001b[43m)\u001b[49m\n",
      "\u001b[1;31mFileNotFoundError\u001b[0m: [Errno 2] No such file or directory: 'nortind_small.sqlite'",
      "\nDuring handling of the above exception, another exception occurred:\n",
      "\u001b[1;31mRuntimeError\u001b[0m                              Traceback (most recent call last)",
      "Cell \u001b[1;32mIn[13], line 4\u001b[0m\n\u001b[0;32m      2\u001b[0m     \u001b[38;5;28mopen\u001b[39m(\u001b[38;5;124m\"\u001b[39m\u001b[38;5;124mnortind_small.sqlite\u001b[39m\u001b[38;5;124m\"\u001b[39m)\n\u001b[0;32m      3\u001b[0m \u001b[38;5;28;01mexcept\u001b[39;00m \u001b[38;5;167;01mOSError\u001b[39;00m:\n\u001b[1;32m----> 4\u001b[0m     \u001b[38;5;28;01mraise\u001b[39;00m \u001b[38;5;167;01mRuntimeError\u001b[39;00m(\u001b[38;5;124m\"\u001b[39m\u001b[38;5;124munable to handle error\u001b[39m\u001b[38;5;124m\"\u001b[39m)\n",
      "\u001b[1;31mRuntimeError\u001b[0m: unable to handle error"
     ]
    }
   ],
   "source": [
    "try:\n",
    "    open(\"nortind_small.sqlite\")\n",
    "except OSError:\n",
    "    raise RuntimeError(\"unable to handle error\")"
   ]
  },
  {
   "cell_type": "markdown",
   "id": "532b9902-a035-46e0-ad80-ef563e0f2b72",
   "metadata": {},
   "source": [
    "To indicate that an exception is a direct consequence of another, the `raise` statement allows an optional `from` clause:\n",
    "\n",
    "```\n",
    "# exc must be exception instance or None.\n",
    "    raise RuntimeError from exc\n",
    "```"
   ]
  },
  {
   "cell_type": "code",
   "execution_count": 14,
   "id": "24c53973-87c5-4f08-a33e-25eb306613b9",
   "metadata": {},
   "outputs": [
    {
     "ename": "RuntimeError",
     "evalue": "failed to open database",
     "output_type": "error",
     "traceback": [
      "\u001b[1;31m---------------------------------------------------------------------------\u001b[0m",
      "\u001b[1;31mConnectionError\u001b[0m                           Traceback (most recent call last)",
      "Cell \u001b[1;32mIn[14], line 5\u001b[0m\n\u001b[0;32m      4\u001b[0m \u001b[38;5;28;01mtry\u001b[39;00m:\n\u001b[1;32m----> 5\u001b[0m     \u001b[43mfunc\u001b[49m\u001b[43m(\u001b[49m\u001b[43m)\u001b[49m\n\u001b[0;32m      6\u001b[0m \u001b[38;5;28;01mexcept\u001b[39;00m \u001b[38;5;167;01mConnectionError\u001b[39;00m \u001b[38;5;28;01mas\u001b[39;00m exc:\n",
      "Cell \u001b[1;32mIn[14], line 2\u001b[0m, in \u001b[0;36mfunc\u001b[1;34m()\u001b[0m\n\u001b[0;32m      1\u001b[0m \u001b[38;5;28;01mdef\u001b[39;00m \u001b[38;5;21mfunc\u001b[39m():\n\u001b[1;32m----> 2\u001b[0m     \u001b[38;5;28;01mraise\u001b[39;00m \u001b[38;5;167;01mConnectionError\u001b[39;00m\n",
      "\u001b[1;31mConnectionError\u001b[0m: ",
      "\nThe above exception was the direct cause of the following exception:\n",
      "\u001b[1;31mRuntimeError\u001b[0m                              Traceback (most recent call last)",
      "Cell \u001b[1;32mIn[14], line 7\u001b[0m\n\u001b[0;32m      5\u001b[0m     func()\n\u001b[0;32m      6\u001b[0m \u001b[38;5;28;01mexcept\u001b[39;00m \u001b[38;5;167;01mConnectionError\u001b[39;00m \u001b[38;5;28;01mas\u001b[39;00m exc:\n\u001b[1;32m----> 7\u001b[0m     \u001b[38;5;28;01mraise\u001b[39;00m \u001b[38;5;167;01mRuntimeError\u001b[39;00m(\u001b[38;5;124m\"\u001b[39m\u001b[38;5;124mfailed to open database\u001b[39m\u001b[38;5;124m\"\u001b[39m) \u001b[38;5;28;01mfrom\u001b[39;00m \u001b[38;5;21;01mexc\u001b[39;00m\n",
      "\u001b[1;31mRuntimeError\u001b[0m: failed to open database"
     ]
    }
   ],
   "source": [
    "def func():\n",
    "    raise ConnectionError\n",
    "\n",
    "try:\n",
    "    func()\n",
    "except ConnectionError as exc:\n",
    "    raise RuntimeError(\"failed to open database\") from exc"
   ]
  },
  {
   "cell_type": "markdown",
   "id": "a584d575-6718-49c3-b9fa-446812385e26",
   "metadata": {},
   "source": [
    "It also allows disabling automatic exception chaining using the `from None` idiom:"
   ]
  },
  {
   "cell_type": "code",
   "execution_count": 15,
   "id": "44253dac-d3e0-42aa-9f35-a9158b5d87b5",
   "metadata": {},
   "outputs": [
    {
     "ename": "RuntimeError",
     "evalue": "",
     "output_type": "error",
     "traceback": [
      "\u001b[1;31m---------------------------------------------------------------------------\u001b[0m",
      "\u001b[1;31mRuntimeError\u001b[0m                              Traceback (most recent call last)",
      "Cell \u001b[1;32mIn[15], line 4\u001b[0m\n\u001b[0;32m      2\u001b[0m     \u001b[38;5;28mopen\u001b[39m(\u001b[38;5;124m'\u001b[39m\u001b[38;5;124mnortwind.sqlite\u001b[39m\u001b[38;5;124m'\u001b[39m)\n\u001b[0;32m      3\u001b[0m \u001b[38;5;28;01mexcept\u001b[39;00m \u001b[38;5;167;01mOSError\u001b[39;00m:\n\u001b[1;32m----> 4\u001b[0m     \u001b[38;5;28;01mraise\u001b[39;00m \u001b[38;5;167;01mRuntimeError\u001b[39;00m \u001b[38;5;28;01mfrom\u001b[39;00m \u001b[38;5;28;01mNone\u001b[39;00m\n",
      "\u001b[1;31mRuntimeError\u001b[0m: "
     ]
    }
   ],
   "source": [
    "try:\n",
    "    open('nortwind.sqlite')\n",
    "except OSError:\n",
    "    raise RuntimeError from None"
   ]
  },
  {
   "cell_type": "markdown",
   "id": "ef00cf41-c15e-4e2a-9e49-4ee285e0be67",
   "metadata": {},
   "source": [
    "For more information about chaining mechanics, see `Built-in Exceptions`."
   ]
  },
  {
   "cell_type": "markdown",
   "id": "d2858fc8-c9aa-4258-8bde-0f13670cdf78",
   "metadata": {},
   "source": [
    "#### User-defined Exceptions"
   ]
  },
  {
   "cell_type": "markdown",
   "id": "0512ccc0-57c5-4179-9ce4-9ea34d5dafe3",
   "metadata": {},
   "source": [
    "Programs may name their own exceptions by creating a new exception class. Exceptions should typically be derived from the `Exception` class, either directly or indirectly.\n",
    "\n",
    "Exception classes can be defined which do anything any other class can do, but are usually kept simple, often only offering a number of attributes that allow information about the error to be extracted by handlers for the exception.\n",
    "\n",
    "Most exceptions are defined with names that end in “Error”, similar to the naming of the standard exceptions.\n",
    "\n",
    "Many standard modules define their own exceptions to report errors that may occur in functions they define."
   ]
  },
  {
   "cell_type": "markdown",
   "id": "29b86f1f-62c5-4546-8fc9-1a28808cb11e",
   "metadata": {},
   "source": [
    "#### Defining Clean-up Actions"
   ]
  },
  {
   "cell_type": "markdown",
   "id": "3c360e1f-a19c-4f28-bca4-f80f282213b7",
   "metadata": {},
   "source": [
    "The `try` statement has another optional clause which is intended to define clean-up actions that must be executed under all circumstances. For example:"
   ]
  },
  {
   "cell_type": "code",
   "execution_count": 16,
   "id": "0f46c2bf-e4b7-4d88-a1fa-dac68fdb1749",
   "metadata": {},
   "outputs": [
    {
     "name": "stdout",
     "output_type": "stream",
     "text": [
      "Goodbye, world!\n"
     ]
    },
    {
     "ename": "KeyboardInterrupt",
     "evalue": "",
     "output_type": "error",
     "traceback": [
      "\u001b[1;31m---------------------------------------------------------------------------\u001b[0m",
      "\u001b[1;31mKeyboardInterrupt\u001b[0m                         Traceback (most recent call last)",
      "Cell \u001b[1;32mIn[16], line 2\u001b[0m\n\u001b[0;32m      1\u001b[0m \u001b[38;5;28;01mtry\u001b[39;00m:\n\u001b[1;32m----> 2\u001b[0m     \u001b[38;5;28;01mraise\u001b[39;00m \u001b[38;5;167;01mKeyboardInterrupt\u001b[39;00m\n\u001b[0;32m      3\u001b[0m \u001b[38;5;28;01mfinally\u001b[39;00m:\n\u001b[0;32m      4\u001b[0m     \u001b[38;5;28mprint\u001b[39m(\u001b[38;5;124m'\u001b[39m\u001b[38;5;124mGoodbye, world!\u001b[39m\u001b[38;5;124m'\u001b[39m)\n",
      "\u001b[1;31mKeyboardInterrupt\u001b[0m: "
     ]
    }
   ],
   "source": [
    "try:\n",
    "    raise KeyboardInterrupt\n",
    "finally:\n",
    "    print('Goodbye, world!')"
   ]
  },
  {
   "cell_type": "markdown",
   "id": "d162f1ec-ebce-42e2-956d-60940e193d26",
   "metadata": {},
   "source": [
    "If a `finally` clause is present, the finally clause will execute as the last task before the `try` statement completes. The finally clause runs whether or not the try statement produces an exception. The following points discuss more complex cases when an exception occurs:\n",
    "\n",
    "- If an exception occurs during execution of the try clause, the exception may be handled by an `except` clause. If the exception is not handled by an except clause, the exception is re-raised after the finally clause has been executed.\n",
    "\n",
    "- An exception could occur during execution of an except or else clause. Again, the exception is re-raised after the finally clause has been executed.\n",
    "\n",
    "- If the finally clause executes a `break`, `continue` or `return` statement, exceptions are not re-raised.\n",
    "\n",
    "- If the try statement reaches a `break`, `continue` or `return` statement, the finally clause will execute just prior to the break, continue or return statement’s execution.\n",
    "\n",
    "- If a finally clause includes a return statement, the returned value will be the one from the finally clause’s return statement, not the value from the try clause’s return statement."
   ]
  },
  {
   "cell_type": "code",
   "execution_count": 17,
   "id": "f6463a76-9548-4ac0-b89d-a3c71f676a7f",
   "metadata": {},
   "outputs": [
    {
     "data": {
      "text/plain": [
       "False"
      ]
     },
     "execution_count": 17,
     "metadata": {},
     "output_type": "execute_result"
    }
   ],
   "source": [
    "def ret():\n",
    "    try:\n",
    "        return True\n",
    "    finally:\n",
    "        return False\n",
    "\n",
    "ret()"
   ]
  },
  {
   "cell_type": "code",
   "execution_count": 33,
   "id": "2ae4420c-e860-4250-b23d-67048f6e788e",
   "metadata": {},
   "outputs": [],
   "source": [
    "def divide(x, y):\n",
    "    try:\n",
    "        result = x / y\n",
    "    except ZeroDivisionError:\n",
    "        print(\"division by zero!\")\n",
    "    else:\n",
    "        print(\"result is\", result)\n",
    "    finally:\n",
    "        print(\"executing finally clause\")"
   ]
  },
  {
   "cell_type": "code",
   "execution_count": 39,
   "id": "523d3929-1763-49ed-b9d7-a488cb678155",
   "metadata": {},
   "outputs": [
    {
     "name": "stdout",
     "output_type": "stream",
     "text": [
      "result is 2.0\n",
      "executing finally clause\n",
      "None\n",
      "\n",
      "\n",
      "result is -0.3333333333333333\n",
      "executing finally clause\n",
      "None\n"
     ]
    }
   ],
   "source": [
    "print(divide(2,1))\n",
    "print(\"\\n\")\n",
    "print(divide(-1,3))"
   ]
  },
  {
   "cell_type": "code",
   "execution_count": 40,
   "id": "93df4b34-8578-4209-808c-1b8411645244",
   "metadata": {},
   "outputs": [
    {
     "name": "stdout",
     "output_type": "stream",
     "text": [
      "division by zero!\n",
      "executing finally clause\n",
      "None\n"
     ]
    }
   ],
   "source": [
    "print(divide(2,0))"
   ]
  },
  {
   "cell_type": "code",
   "execution_count": 41,
   "id": "1c4c9f68-d60a-496f-90f9-862c06037994",
   "metadata": {},
   "outputs": [
    {
     "name": "stdout",
     "output_type": "stream",
     "text": [
      "executing finally clause\n"
     ]
    },
    {
     "ename": "TypeError",
     "evalue": "unsupported operand type(s) for /: 'str' and 'str'",
     "output_type": "error",
     "traceback": [
      "\u001b[1;31m---------------------------------------------------------------------------\u001b[0m",
      "\u001b[1;31mTypeError\u001b[0m                                 Traceback (most recent call last)",
      "Cell \u001b[1;32mIn[41], line 1\u001b[0m\n\u001b[1;32m----> 1\u001b[0m \u001b[38;5;28mprint\u001b[39m(\u001b[43mdivide\u001b[49m\u001b[43m(\u001b[49m\u001b[38;5;124;43m\"\u001b[39;49m\u001b[38;5;124;43m2\u001b[39;49m\u001b[38;5;124;43m\"\u001b[39;49m\u001b[43m,\u001b[49m\u001b[38;5;124;43m\"\u001b[39;49m\u001b[38;5;124;43m1\u001b[39;49m\u001b[38;5;124;43m\"\u001b[39;49m\u001b[43m)\u001b[49m) \u001b[38;5;66;03m# finally clause still even after fatal error occurs executes\u001b[39;00m\n",
      "Cell \u001b[1;32mIn[33], line 3\u001b[0m, in \u001b[0;36mdivide\u001b[1;34m(x, y)\u001b[0m\n\u001b[0;32m      1\u001b[0m \u001b[38;5;28;01mdef\u001b[39;00m \u001b[38;5;21mdivide\u001b[39m(x, y):\n\u001b[0;32m      2\u001b[0m     \u001b[38;5;28;01mtry\u001b[39;00m:\n\u001b[1;32m----> 3\u001b[0m         result \u001b[38;5;241m=\u001b[39m \u001b[43mx\u001b[49m\u001b[43m \u001b[49m\u001b[38;5;241;43m/\u001b[39;49m\u001b[43m \u001b[49m\u001b[43my\u001b[49m\n\u001b[0;32m      4\u001b[0m     \u001b[38;5;28;01mexcept\u001b[39;00m \u001b[38;5;167;01mZeroDivisionError\u001b[39;00m:\n\u001b[0;32m      5\u001b[0m         \u001b[38;5;28mprint\u001b[39m(\u001b[38;5;124m\"\u001b[39m\u001b[38;5;124mdivision by zero!\u001b[39m\u001b[38;5;124m\"\u001b[39m)\n",
      "\u001b[1;31mTypeError\u001b[0m: unsupported operand type(s) for /: 'str' and 'str'"
     ]
    }
   ],
   "source": [
    "print(divide(\"2\",\"1\")) # finally clause still even after fatal error occurs executes"
   ]
  },
  {
   "cell_type": "markdown",
   "id": "6dfa2927-e9cf-4327-82cb-966429c7a347",
   "metadata": {},
   "source": [
    "As you can see, the `finally` clause is executed in any event. The `TypeError` raised by dividing two strings is not handled by the `except` clause and therefore re-raised after the finally clause has been executed.\n",
    "\n",
    "In real world applications, the `finally` clause is useful for releasing external resources (such as files or network connections), regardless of whether the use of the resource was successful."
   ]
  },
  {
   "cell_type": "markdown",
   "id": "3361667b-4624-4214-ae60-f8a6a2ee6440",
   "metadata": {},
   "source": [
    "#### Predefined Clean-up Actions"
   ]
  },
  {
   "cell_type": "markdown",
   "id": "c3eb8046-0e42-493f-ace0-dbb5118ee43b",
   "metadata": {},
   "source": [
    "Some objects define standard clean-up actions to be undertaken when the object is no longer needed, regardless of whether or not the operation using the object succeeded or failed. Look at the following example, which tries to open a file and print its contents to the screen."
   ]
  },
  {
   "cell_type": "code",
   "execution_count": 22,
   "id": "9cba2ec7-fef5-4ff3-aa92-2d2f9bbbeb70",
   "metadata": {},
   "outputs": [
    {
     "name": "stdout",
     "output_type": "stream",
     "text": [
      "0123456789abcdefxt line is appended to the existing text\n",
      "('winning lottery price ', 24342241)"
     ]
    }
   ],
   "source": [
    "for line in open(\"workfile\"):\n",
    "    print(line, end=\"\")"
   ]
  },
  {
   "cell_type": "markdown",
   "id": "11e71e6f-5d3b-4962-8724-e8e448bdd1e1",
   "metadata": {},
   "source": [
    "The issue with this code is that it leaves the file open for an indeterminate amount of time after this part of the code has finished executing. This is not an issue in simple scripts, but can be a problem for larger applications. The `with` statement allows objects like files to be used in a way that ensures they are always cleaned up promptly and correctly."
   ]
  },
  {
   "cell_type": "code",
   "execution_count": 23,
   "id": "d4174f07-ec14-44e9-8eff-04d50554a868",
   "metadata": {},
   "outputs": [
    {
     "name": "stdout",
     "output_type": "stream",
     "text": [
      "0123456789abcdefxt line is appended to the existing text\n",
      "('winning lottery price ', 24342241)"
     ]
    }
   ],
   "source": [
    "with open(\"workfile\") as f:\n",
    "    for line in f:\n",
    "        print(line, end=\"\")"
   ]
  },
  {
   "cell_type": "markdown",
   "id": "8b302c7a-4bdb-461f-94ed-c350185a654e",
   "metadata": {},
   "source": [
    "After the statement is executed, the file f is always closed, even if a problem was encountered while processing the lines. Objects which, like files, provide predefined clean-up actions will indicate this in their documentation."
   ]
  },
  {
   "cell_type": "markdown",
   "id": "57a1cbe7-b1fd-4b92-bc12-deb1496ae864",
   "metadata": {},
   "source": [
    "#### Raising and Handling Multiple Unrelated Exceptions"
   ]
  },
  {
   "cell_type": "code",
   "execution_count": 24,
   "id": "a3468f99-df9a-457b-b733-5a1e4d5b7a86",
   "metadata": {},
   "outputs": [
    {
     "name": "stderr",
     "output_type": "stream",
     "text": [
      "  + Exception Group Traceback (most recent call last):\n",
      "  |   File \"C:\\Program Files\\Python312\\Lib\\site-packages\\IPython\\core\\interactiveshell.py\", line 3577, in run_code\n",
      "  |     exec(code_obj, self.user_global_ns, self.user_ns)\n",
      "  |   File \"C:\\Users\\PC\\AppData\\Local\\Temp\\ipykernel_5212\\3010321890.py\", line 4, in <module>\n",
      "  |     f()\n",
      "  |   File \"C:\\Users\\PC\\AppData\\Local\\Temp\\ipykernel_5212\\3010321890.py\", line 3, in f\n",
      "  |     raise ExceptionGroup('there were problems', excs)\n",
      "  | ExceptionGroup: there were problems (2 sub-exceptions)\n",
      "  +-+---------------- 1 ----------------\n",
      "    | OSError: error 1\n",
      "    +---------------- 2 ----------------\n",
      "    | SystemError: error 2\n",
      "    +------------------------------------\n"
     ]
    }
   ],
   "source": [
    "def f():\n",
    "    excs = [OSError('error 1'), SystemError('error 2')]\n",
    "    raise ExceptionGroup('there were problems', excs)\n",
    "f()\n",
    "\n",
    "try:\n",
    "    f()\n",
    "except Exception as e:\n",
    "    print(f'caught {type(e)}: e')\n",
    "\n"
   ]
  },
  {
   "cell_type": "markdown",
   "id": "2ea3b0b7-f4ee-47a9-bbe8-fea367a96fca",
   "metadata": {},
   "source": [
    "By using except* instead of except, we can selectively handle only the exceptions in the group that match a certain type. In the following example, which shows a nested exception group, each except* clause extracts from the group exceptions of a certain type while letting all other exceptions propagate to other clauses and eventually to be reraised.\n",
    "\n"
   ]
  },
  {
   "cell_type": "code",
   "execution_count": 25,
   "id": "0bdbe988-afdd-4cb5-b1aa-9842741ddfeb",
   "metadata": {},
   "outputs": [
    {
     "name": "stdout",
     "output_type": "stream",
     "text": [
      "There were OSErrors\n",
      "There were SystemErrors\n"
     ]
    },
    {
     "name": "stderr",
     "output_type": "stream",
     "text": [
      "  + Exception Group Traceback (most recent call last):\n",
      "  |   File \"C:\\Program Files\\Python312\\Lib\\site-packages\\IPython\\core\\interactiveshell.py\", line 3577, in run_code\n",
      "  |     exec(code_obj, self.user_global_ns, self.user_ns)\n",
      "  |   File \"C:\\Users\\PC\\AppData\\Local\\Temp\\ipykernel_5212\\1308333313.py\", line 18, in <module>\n",
      "  |     f()\n",
      "  |   File \"C:\\Users\\PC\\AppData\\Local\\Temp\\ipykernel_5212\\1308333313.py\", line 2, in f\n",
      "  |     raise ExceptionGroup(\n",
      "  | ExceptionGroup: group1 (1 sub-exception)\n",
      "  +-+---------------- 1 ----------------\n",
      "    | ExceptionGroup: group2 (1 sub-exception)\n",
      "    +-+---------------- 1 ----------------\n",
      "      | RecursionError: 4\n",
      "      +------------------------------------\n"
     ]
    }
   ],
   "source": [
    "def f():\n",
    "    raise ExceptionGroup(\n",
    "        \"group1\",\n",
    "        [\n",
    "            OSError(1),\n",
    "            SystemError(2),\n",
    "            ExceptionGroup(\n",
    "                \"group2\",\n",
    "                [\n",
    "                    OSError(3),\n",
    "                    RecursionError(4)\n",
    "                ]\n",
    "            )\n",
    "        ]\n",
    "    )\n",
    "\n",
    "try:\n",
    "    f()\n",
    "except* OSError as e:\n",
    "    print(\"There were OSErrors\")\n",
    "except* SystemError as e:\n",
    "    print(\"There were SystemErrors\")"
   ]
  },
  {
   "cell_type": "markdown",
   "id": "18605290-527f-4bd8-8f4d-1bb322143cfa",
   "metadata": {},
   "source": [
    "Note that the exceptions nested in an exception group must be instances, not types. This is because in practice the exceptions would typically be ones that have already been raised and caught by the program, along the following pattern:"
   ]
  },
  {
   "cell_type": "code",
   "execution_count": 26,
   "id": "3769b3d5-80e9-4c59-9a67-c5900667e16e",
   "metadata": {},
   "outputs": [],
   "source": [
    "excs = []\n",
    "for test in excs:\n",
    "    try:\n",
    "        test.run()\n",
    "    except Exception as e:\n",
    "        excs.append(e)\n",
    "\n",
    "if excs:\n",
    "    raise ExceptionGroup(\"Test Failures\", excs)"
   ]
  },
  {
   "cell_type": "markdown",
   "id": "c54b208f-3a88-4e62-b3c6-4869deb7268a",
   "metadata": {},
   "source": [
    " #### Enriching Exceptions with Notes"
   ]
  },
  {
   "cell_type": "markdown",
   "id": "013493b5-4616-4f14-948b-ce5ea4d7e621",
   "metadata": {},
   "source": [
    "When an exception is created in order to be raised, it is usually initialized with information that describes the error that has occurred. There are cases where it is useful to add information after the exception was caught. For this purpose, exceptions have a method add_note(note) that accepts a string and adds it to the exception’s notes list. The standard traceback rendering includes all notes, in the order they were added, after the exception."
   ]
  },
  {
   "cell_type": "code",
   "execution_count": 27,
   "id": "b1a95a6b-d886-4f1d-9dfb-5b56a3295c25",
   "metadata": {},
   "outputs": [
    {
     "ename": "TypeError",
     "evalue": "bad type",
     "output_type": "error",
     "traceback": [
      "\u001b[1;31m---------------------------------------------------------------------------\u001b[0m",
      "\u001b[1;31mTypeError\u001b[0m                                 Traceback (most recent call last)",
      "Cell \u001b[1;32mIn[27], line 2\u001b[0m\n\u001b[0;32m      1\u001b[0m \u001b[38;5;28;01mtry\u001b[39;00m:\n\u001b[1;32m----> 2\u001b[0m     \u001b[38;5;28;01mraise\u001b[39;00m \u001b[38;5;167;01mTypeError\u001b[39;00m(\u001b[38;5;124m'\u001b[39m\u001b[38;5;124mbad type\u001b[39m\u001b[38;5;124m'\u001b[39m)\n\u001b[0;32m      3\u001b[0m \u001b[38;5;28;01mexcept\u001b[39;00m \u001b[38;5;167;01mException\u001b[39;00m \u001b[38;5;28;01mas\u001b[39;00m e:\n\u001b[0;32m      4\u001b[0m     e\u001b[38;5;241m.\u001b[39madd_note(\u001b[38;5;124m'\u001b[39m\u001b[38;5;124mAdd some information\u001b[39m\u001b[38;5;124m'\u001b[39m)\n",
      "\u001b[1;31mTypeError\u001b[0m: bad type",
      "\u001b[0mAdd some information",
      "\u001b[0mAdd some more information"
     ]
    }
   ],
   "source": [
    "try:\n",
    "    raise TypeError('bad type')\n",
    "except Exception as e:\n",
    "    e.add_note('Add some information')\n",
    "    e.add_note('Add some more information')\n",
    "    raise"
   ]
  },
  {
   "cell_type": "markdown",
   "id": "0453a2cf-c29d-4c62-99bf-fb607e54a86c",
   "metadata": {},
   "source": [
    "For example, when collecting exceptions into an exception group, we may want to add context information for the individual errors. In the following each exception in the group has a note indicating when this error has occurred."
   ]
  },
  {
   "cell_type": "code",
   "execution_count": 28,
   "id": "724370b1-1627-402a-ae55-5d63e0b23803",
   "metadata": {},
   "outputs": [
    {
     "name": "stderr",
     "output_type": "stream",
     "text": [
      "  + Exception Group Traceback (most recent call last):\n",
      "  |   File \"C:\\Program Files\\Python312\\Lib\\site-packages\\IPython\\core\\interactiveshell.py\", line 3577, in run_code\n",
      "  |     exec(code_obj, self.user_global_ns, self.user_ns)\n",
      "  |   File \"C:\\Users\\PC\\AppData\\Local\\Temp\\ipykernel_5212\\1429863547.py\", line 12, in <module>\n",
      "  |     raise ExceptionGroup('We have some problems', excs)\n",
      "  | ExceptionGroup: We have some problems (3 sub-exceptions)\n",
      "  +-+---------------- 1 ----------------\n",
      "    | Traceback (most recent call last):\n",
      "    |   File \"C:\\Users\\PC\\AppData\\Local\\Temp\\ipykernel_5212\\1429863547.py\", line 7, in <module>\n",
      "    |     f()\n",
      "    |   File \"C:\\Users\\PC\\AppData\\Local\\Temp\\ipykernel_5212\\1429863547.py\", line 2, in f\n",
      "    |     raise OSError('operation failed')\n",
      "    | OSError: operation failed\n",
      "    | Happened in Iteration 1\n",
      "    +---------------- 2 ----------------\n",
      "    | Traceback (most recent call last):\n",
      "    |   File \"C:\\Users\\PC\\AppData\\Local\\Temp\\ipykernel_5212\\1429863547.py\", line 7, in <module>\n",
      "    |     f()\n",
      "    |   File \"C:\\Users\\PC\\AppData\\Local\\Temp\\ipykernel_5212\\1429863547.py\", line 2, in f\n",
      "    |     raise OSError('operation failed')\n",
      "    | OSError: operation failed\n",
      "    | Happened in Iteration 2\n",
      "    +---------------- 3 ----------------\n",
      "    | Traceback (most recent call last):\n",
      "    |   File \"C:\\Users\\PC\\AppData\\Local\\Temp\\ipykernel_5212\\1429863547.py\", line 7, in <module>\n",
      "    |     f()\n",
      "    |   File \"C:\\Users\\PC\\AppData\\Local\\Temp\\ipykernel_5212\\1429863547.py\", line 2, in f\n",
      "    |     raise OSError('operation failed')\n",
      "    | OSError: operation failed\n",
      "    | Happened in Iteration 3\n",
      "    +------------------------------------\n"
     ]
    }
   ],
   "source": [
    "def f():\n",
    "    raise OSError('operation failed')\n",
    "\n",
    "excs = []\n",
    "for i in range(3):\n",
    "    try:\n",
    "        f()\n",
    "    except Exception as e:\n",
    "        e.add_note(f'Happened in Iteration {i+1}')\n",
    "        excs.append(e)\n",
    "\n",
    "raise ExceptionGroup('We have some problems', excs)"
   ]
  },
  {
   "cell_type": "code",
   "execution_count": 42,
   "id": "bc9e0c90-69ce-4b1d-af29-72168e0e771b",
   "metadata": {},
   "outputs": [
    {
     "name": "stdout",
     "output_type": "stream",
     "text": [
      "BaseException.__context__: <attribute '__context__' of 'BaseException' objects>\n",
      "BaseException.__cause__: <attribute '__cause__' of 'BaseException' objects>\n",
      "BaseException.__suppress_context__: <member '__suppress_context__' of 'BaseException' objects>\n",
      "\n"
     ]
    }
   ],
   "source": [
    "out = (\n",
    "    f\"BaseException.__context__: {BaseException.__context__}\\n\"\n",
    "    f\"BaseException.__cause__: {BaseException.__cause__}\\n\"\n",
    "    f\"BaseException.__suppress_context__: {BaseException.__suppress_context__}\\n\"\n",
    ")\n",
    "print(out)"
   ]
  },
  {
   "cell_type": "code",
   "execution_count": null,
   "id": "1f68986d-7aa9-469a-a764-a82af54e833c",
   "metadata": {},
   "outputs": [],
   "source": []
  }
 ],
 "metadata": {
  "kernelspec": {
   "display_name": "Python 3 (ipykernel)",
   "language": "python",
   "name": "python3"
  },
  "language_info": {
   "codemirror_mode": {
    "name": "ipython",
    "version": 3
   },
   "file_extension": ".py",
   "mimetype": "text/x-python",
   "name": "python",
   "nbconvert_exporter": "python",
   "pygments_lexer": "ipython3",
   "version": "3.12.3"
  }
 },
 "nbformat": 4,
 "nbformat_minor": 5
}
